{
  "nbformat": 4,
  "nbformat_minor": 0,
  "metadata": {
    "colab": {
      "provenance": [],
      "gpuType": "T4"
    },
    "kernelspec": {
      "name": "python3",
      "display_name": "Python 3"
    },
    "language_info": {
      "name": "python"
    },
    "accelerator": "GPU"
  },
  "cells": [
    {
      "cell_type": "code",
      "execution_count": 5,
      "metadata": {
        "colab": {
          "base_uri": "https://localhost:8080/"
        },
        "id": "LlNsdhrb7vmx",
        "outputId": "94a67cab-434e-4dc8-d739-9bbc197c0f15"
      },
      "outputs": [
        {
          "output_type": "stream",
          "name": "stdout",
          "text": [
            "Collecting python-telegram-bot\n",
            "  Downloading python_telegram_bot-21.10-py3-none-any.whl.metadata (17 kB)\n",
            "Requirement already satisfied: httpx~=0.27 in /usr/local/lib/python3.11/dist-packages (from python-telegram-bot) (0.28.1)\n",
            "Requirement already satisfied: anyio in /usr/local/lib/python3.11/dist-packages (from httpx~=0.27->python-telegram-bot) (3.7.1)\n",
            "Requirement already satisfied: certifi in /usr/local/lib/python3.11/dist-packages (from httpx~=0.27->python-telegram-bot) (2024.12.14)\n",
            "Requirement already satisfied: httpcore==1.* in /usr/local/lib/python3.11/dist-packages (from httpx~=0.27->python-telegram-bot) (1.0.7)\n",
            "Requirement already satisfied: idna in /usr/local/lib/python3.11/dist-packages (from httpx~=0.27->python-telegram-bot) (3.10)\n",
            "Requirement already satisfied: h11<0.15,>=0.13 in /usr/local/lib/python3.11/dist-packages (from httpcore==1.*->httpx~=0.27->python-telegram-bot) (0.14.0)\n",
            "Requirement already satisfied: sniffio>=1.1 in /usr/local/lib/python3.11/dist-packages (from anyio->httpx~=0.27->python-telegram-bot) (1.3.1)\n",
            "Downloading python_telegram_bot-21.10-py3-none-any.whl (669 kB)\n",
            "\u001b[?25l   \u001b[90m━━━━━━━━━━━━━━━━━━━━━━━━━━━━━━━━━━━━━━━━\u001b[0m \u001b[32m0.0/669.5 kB\u001b[0m \u001b[31m?\u001b[0m eta \u001b[36m-:--:--\u001b[0m\r\u001b[2K   \u001b[90m━━━━━━━━━━━━━━━━━━━━━━━━━━━━━━━━━━━━━━━━\u001b[0m \u001b[32m669.5/669.5 kB\u001b[0m \u001b[31m37.3 MB/s\u001b[0m eta \u001b[36m0:00:00\u001b[0m\n",
            "\u001b[?25hInstalling collected packages: python-telegram-bot\n",
            "Successfully installed python-telegram-bot-21.10\n",
            "Requirement already satisfied: torch in /usr/local/lib/python3.11/dist-packages (2.5.1+cu121)\n",
            "Requirement already satisfied: transformers in /usr/local/lib/python3.11/dist-packages (4.47.1)\n",
            "Requirement already satisfied: filelock in /usr/local/lib/python3.11/dist-packages (from torch) (3.17.0)\n",
            "Requirement already satisfied: typing-extensions>=4.8.0 in /usr/local/lib/python3.11/dist-packages (from torch) (4.12.2)\n",
            "Requirement already satisfied: networkx in /usr/local/lib/python3.11/dist-packages (from torch) (3.4.2)\n",
            "Requirement already satisfied: jinja2 in /usr/local/lib/python3.11/dist-packages (from torch) (3.1.5)\n",
            "Requirement already satisfied: fsspec in /usr/local/lib/python3.11/dist-packages (from torch) (2024.10.0)\n",
            "Requirement already satisfied: nvidia-cuda-nvrtc-cu12==12.1.105 in /usr/local/lib/python3.11/dist-packages (from torch) (12.1.105)\n",
            "Requirement already satisfied: nvidia-cuda-runtime-cu12==12.1.105 in /usr/local/lib/python3.11/dist-packages (from torch) (12.1.105)\n",
            "Requirement already satisfied: nvidia-cuda-cupti-cu12==12.1.105 in /usr/local/lib/python3.11/dist-packages (from torch) (12.1.105)\n",
            "Requirement already satisfied: nvidia-cudnn-cu12==9.1.0.70 in /usr/local/lib/python3.11/dist-packages (from torch) (9.1.0.70)\n",
            "Requirement already satisfied: nvidia-cublas-cu12==12.1.3.1 in /usr/local/lib/python3.11/dist-packages (from torch) (12.1.3.1)\n",
            "Requirement already satisfied: nvidia-cufft-cu12==11.0.2.54 in /usr/local/lib/python3.11/dist-packages (from torch) (11.0.2.54)\n",
            "Requirement already satisfied: nvidia-curand-cu12==10.3.2.106 in /usr/local/lib/python3.11/dist-packages (from torch) (10.3.2.106)\n",
            "Requirement already satisfied: nvidia-cusolver-cu12==11.4.5.107 in /usr/local/lib/python3.11/dist-packages (from torch) (11.4.5.107)\n",
            "Requirement already satisfied: nvidia-cusparse-cu12==12.1.0.106 in /usr/local/lib/python3.11/dist-packages (from torch) (12.1.0.106)\n",
            "Requirement already satisfied: nvidia-nccl-cu12==2.21.5 in /usr/local/lib/python3.11/dist-packages (from torch) (2.21.5)\n",
            "Requirement already satisfied: nvidia-nvtx-cu12==12.1.105 in /usr/local/lib/python3.11/dist-packages (from torch) (12.1.105)\n",
            "Requirement already satisfied: triton==3.1.0 in /usr/local/lib/python3.11/dist-packages (from torch) (3.1.0)\n",
            "Requirement already satisfied: sympy==1.13.1 in /usr/local/lib/python3.11/dist-packages (from torch) (1.13.1)\n",
            "Requirement already satisfied: nvidia-nvjitlink-cu12 in /usr/local/lib/python3.11/dist-packages (from nvidia-cusolver-cu12==11.4.5.107->torch) (12.6.85)\n",
            "Requirement already satisfied: mpmath<1.4,>=1.1.0 in /usr/local/lib/python3.11/dist-packages (from sympy==1.13.1->torch) (1.3.0)\n",
            "Requirement already satisfied: huggingface-hub<1.0,>=0.24.0 in /usr/local/lib/python3.11/dist-packages (from transformers) (0.27.1)\n",
            "Requirement already satisfied: numpy>=1.17 in /usr/local/lib/python3.11/dist-packages (from transformers) (1.26.4)\n",
            "Requirement already satisfied: packaging>=20.0 in /usr/local/lib/python3.11/dist-packages (from transformers) (24.2)\n",
            "Requirement already satisfied: pyyaml>=5.1 in /usr/local/lib/python3.11/dist-packages (from transformers) (6.0.2)\n",
            "Requirement already satisfied: regex!=2019.12.17 in /usr/local/lib/python3.11/dist-packages (from transformers) (2024.11.6)\n",
            "Requirement already satisfied: requests in /usr/local/lib/python3.11/dist-packages (from transformers) (2.32.3)\n",
            "Requirement already satisfied: tokenizers<0.22,>=0.21 in /usr/local/lib/python3.11/dist-packages (from transformers) (0.21.0)\n",
            "Requirement already satisfied: safetensors>=0.4.1 in /usr/local/lib/python3.11/dist-packages (from transformers) (0.5.2)\n",
            "Requirement already satisfied: tqdm>=4.27 in /usr/local/lib/python3.11/dist-packages (from transformers) (4.67.1)\n",
            "Requirement already satisfied: MarkupSafe>=2.0 in /usr/local/lib/python3.11/dist-packages (from jinja2->torch) (3.0.2)\n",
            "Requirement already satisfied: charset-normalizer<4,>=2 in /usr/local/lib/python3.11/dist-packages (from requests->transformers) (3.4.1)\n",
            "Requirement already satisfied: idna<4,>=2.5 in /usr/local/lib/python3.11/dist-packages (from requests->transformers) (3.10)\n",
            "Requirement already satisfied: urllib3<3,>=1.21.1 in /usr/local/lib/python3.11/dist-packages (from requests->transformers) (2.3.0)\n",
            "Requirement already satisfied: certifi>=2017.4.17 in /usr/local/lib/python3.11/dist-packages (from requests->transformers) (2024.12.14)\n",
            "Requirement already satisfied: python-telegram-bot in /usr/local/lib/python3.11/dist-packages (21.10)\n",
            "Requirement already satisfied: httpx~=0.27 in /usr/local/lib/python3.11/dist-packages (from python-telegram-bot) (0.28.1)\n",
            "Requirement already satisfied: anyio in /usr/local/lib/python3.11/dist-packages (from httpx~=0.27->python-telegram-bot) (3.7.1)\n",
            "Requirement already satisfied: certifi in /usr/local/lib/python3.11/dist-packages (from httpx~=0.27->python-telegram-bot) (2024.12.14)\n",
            "Requirement already satisfied: httpcore==1.* in /usr/local/lib/python3.11/dist-packages (from httpx~=0.27->python-telegram-bot) (1.0.7)\n",
            "Requirement already satisfied: idna in /usr/local/lib/python3.11/dist-packages (from httpx~=0.27->python-telegram-bot) (3.10)\n",
            "Requirement already satisfied: h11<0.15,>=0.13 in /usr/local/lib/python3.11/dist-packages (from httpcore==1.*->httpx~=0.27->python-telegram-bot) (0.14.0)\n",
            "Requirement already satisfied: sniffio>=1.1 in /usr/local/lib/python3.11/dist-packages (from anyio->httpx~=0.27->python-telegram-bot) (1.3.1)\n"
          ]
        }
      ],
      "source": [
        "!pip install python-telegram-bot\n",
        "!pip install torch transformers\n",
        "!pip install python-telegram-bot --upgrade"
      ]
    },
    {
      "cell_type": "code",
      "source": [
        "from transformers import pipeline\n",
        "from telegram import Update\n",
        "from telegram.ext import Application, CommandHandler, MessageHandler, filters, ContextTypes\n",
        "import asyncio\n",
        "import nest_asyncio\n",
        "\n",
        "nest_asyncio.apply()\n",
        "\n",
        "text_generator = pipeline(\n",
        "    \"text-generation\",\n",
        "    model=\"TinyLlama/TinyLlama-1.1B-Chat-v1.0\",\n",
        "    max_new_tokens=300,\n",
        "    device=\"cuda\",\n",
        "    do_sample=True,\n",
        "    temperature=0.7,\n",
        "    pad_token_id=50256,\n",
        "    eos_token_id=50256,\n",
        "    truncation=True\n",
        ")\n",
        "\n",
        "def truncate_to_full_stop(text: str, max_chars: int) -> str:\n",
        "    \"\"\"\n",
        "    Truncate the text to the last full stop before reaching the max character limit.\n",
        "    \"\"\"\n",
        "    if len(text) <= max_chars:\n",
        "        return text\n",
        "    truncated = text[:max_chars]\n",
        "    last_full_stop = truncated.rfind(\".\")\n",
        "    if last_full_stop != -1:\n",
        "        return truncated[:last_full_stop + 1]\n",
        "    return truncated\n",
        "\n",
        "async def start(update: Update, context: ContextTypes.DEFAULT_TYPE) -> None:\n",
        "    await update.message.reply_text(\n",
        "        \"Hi there! I’m your AI assistant powered by TinyLlama. 😊\\n\"\n",
        "        \"Ask me anything or share your thoughts, and I'll do my best to help!\"\n",
        "    )\n",
        "\n",
        "async def process(update: Update, context: ContextTypes.DEFAULT_TYPE) -> None:\n",
        "    processing_message = await update.message.reply_text(\"Let me think...\")\n",
        "\n",
        "    try:\n",
        "        user_input = f\"<human>: {update.message.text}\\n<assistant>:\"\n",
        "        generated = text_generator(user_input, num_return_sequences=1)\n",
        "        full_response = generated[0][\"generated_text\"]\n",
        "\n",
        "        response_text = full_response.split(\"<assistant>:\")[-1].strip()\n",
        "        if \"<human>:\" in response_text:\n",
        "            response_text = response_text.split(\"<human>:\")[0].strip()\n",
        "\n",
        "        response_text = truncate_to_full_stop(response_text, max_chars=300)\n",
        "\n",
        "        if len(response_text) < 10:\n",
        "            response_text = \"Hmm, could you rephrase that? I didn’t quite get it.\"\n",
        "\n",
        "        await processing_message.delete()\n",
        "        await update.message.reply_text(response_text)\n",
        "\n",
        "    except Exception as e:\n",
        "        error_message = f\"Oops, something went wrong: {str(e)}\"\n",
        "        await processing_message.delete()\n",
        "        await update.message.reply_text(error_message)\n",
        "\n",
        "async def main():\n",
        "    TOKEN = \"7626859522:AAEoBP0ysfamXjG1-7UqpvXhVBpKDYE0Uf4\"\n",
        "    application = Application.builder().token(TOKEN).build()\n",
        "\n",
        "    application.add_handler(CommandHandler(\"start\", start))\n",
        "    application.add_handler(MessageHandler(filters.TEXT & ~filters.COMMAND, process))\n",
        "\n",
        "    print(\"Bot is running... Press Ctrl+C to stop.\")\n",
        "    await application.run_polling()\n",
        "\n",
        "loop = asyncio.get_event_loop()\n",
        "if not loop.is_running():\n",
        "    loop.run_until_complete(main())\n",
        "else:\n",
        "    asyncio.ensure_future(main())\n"
      ],
      "metadata": {
        "colab": {
          "base_uri": "https://localhost:8080/"
        },
        "id": "2KRiWCH08Qid",
        "outputId": "a8f17668-ab8c-48a3-f059-4c6a3a46563e"
      },
      "execution_count": 42,
      "outputs": [
        {
          "output_type": "stream",
          "name": "stderr",
          "text": [
            "Device set to use cuda\n",
            "ERROR:telegram.ext.Application:No error handlers are registered, logging exception.\n",
            "Traceback (most recent call last):\n",
            "  File \"/usr/local/lib/python3.11/dist-packages/telegram/ext/_updater.py\", line 750, in _network_loop_retry\n",
            "    if not await do_action():\n",
            "           ^^^^^^^^^^^^^^^^^\n",
            "  File \"/usr/local/lib/python3.11/dist-packages/telegram/ext/_updater.py\", line 744, in do_action\n",
            "    return action_cb_task.result()\n",
            "           ^^^^^^^^^^^^^^^^^^^^^^^\n",
            "  File \"/usr/lib/python3.11/asyncio/futures.py\", line 203, in result\n",
            "    raise self._exception.with_traceback(self._exception_tb)\n",
            "  File \"/usr/lib/python3.11/asyncio/tasks.py\", line 277, in __step\n",
            "    result = coro.send(None)\n",
            "             ^^^^^^^^^^^^^^^\n",
            "  File \"/usr/local/lib/python3.11/dist-packages/telegram/ext/_updater.py\", line 371, in polling_action_cb\n",
            "    updates = await self.bot.get_updates(\n",
            "              ^^^^^^^^^^^^^^^^^^^^^^^^^^^\n",
            "  File \"/usr/local/lib/python3.11/dist-packages/telegram/ext/_extbot.py\", line 650, in get_updates\n",
            "    updates = await super().get_updates(\n",
            "              ^^^^^^^^^^^^^^^^^^^^^^^^^^\n",
            "  File \"/usr/local/lib/python3.11/dist-packages/telegram/_bot.py\", line 4480, in get_updates\n",
            "    await self._post(\n",
            "  File \"/usr/local/lib/python3.11/dist-packages/telegram/_bot.py\", line 619, in _post\n",
            "    return await self._do_post(\n",
            "           ^^^^^^^^^^^^^^^^^^^^\n",
            "  File \"/usr/local/lib/python3.11/dist-packages/telegram/ext/_extbot.py\", line 354, in _do_post\n",
            "    return await super()._do_post(\n",
            "           ^^^^^^^^^^^^^^^^^^^^^^^\n",
            "  File \"/usr/local/lib/python3.11/dist-packages/telegram/_bot.py\", line 648, in _do_post\n",
            "    result = await request.post(\n",
            "             ^^^^^^^^^^^^^^^^^^^\n",
            "  File \"/usr/local/lib/python3.11/dist-packages/telegram/request/_baserequest.py\", line 202, in post\n",
            "    result = await self._request_wrapper(\n",
            "             ^^^^^^^^^^^^^^^^^^^^^^^^^^^^\n",
            "  File \"/usr/local/lib/python3.11/dist-packages/telegram/request/_baserequest.py\", line 385, in _request_wrapper\n",
            "    raise Conflict(message)\n",
            "telegram.error.Conflict: Conflict: terminated by other getUpdates request; make sure that only one bot instance is running\n",
            "ERROR:telegram.ext.Application:No error handlers are registered, logging exception.\n",
            "Traceback (most recent call last):\n",
            "  File \"/usr/local/lib/python3.11/dist-packages/telegram/ext/_updater.py\", line 750, in _network_loop_retry\n",
            "    if not await do_action():\n",
            "           ^^^^^^^^^^^^^^^^^\n",
            "  File \"/usr/local/lib/python3.11/dist-packages/telegram/ext/_updater.py\", line 744, in do_action\n",
            "    return action_cb_task.result()\n",
            "           ^^^^^^^^^^^^^^^^^^^^^^^\n",
            "  File \"/usr/lib/python3.11/asyncio/futures.py\", line 203, in result\n",
            "    raise self._exception.with_traceback(self._exception_tb)\n",
            "  File \"/usr/lib/python3.11/asyncio/tasks.py\", line 277, in __step\n",
            "    result = coro.send(None)\n",
            "             ^^^^^^^^^^^^^^^\n",
            "  File \"/usr/local/lib/python3.11/dist-packages/telegram/ext/_updater.py\", line 371, in polling_action_cb\n",
            "    updates = await self.bot.get_updates(\n",
            "              ^^^^^^^^^^^^^^^^^^^^^^^^^^^\n",
            "  File \"/usr/local/lib/python3.11/dist-packages/telegram/ext/_extbot.py\", line 650, in get_updates\n",
            "    updates = await super().get_updates(\n",
            "              ^^^^^^^^^^^^^^^^^^^^^^^^^^\n",
            "  File \"/usr/local/lib/python3.11/dist-packages/telegram/_bot.py\", line 4480, in get_updates\n",
            "    await self._post(\n",
            "  File \"/usr/local/lib/python3.11/dist-packages/telegram/_bot.py\", line 619, in _post\n",
            "    return await self._do_post(\n",
            "           ^^^^^^^^^^^^^^^^^^^^\n",
            "  File \"/usr/local/lib/python3.11/dist-packages/telegram/ext/_extbot.py\", line 354, in _do_post\n",
            "    return await super()._do_post(\n",
            "           ^^^^^^^^^^^^^^^^^^^^^^^\n",
            "  File \"/usr/local/lib/python3.11/dist-packages/telegram/_bot.py\", line 648, in _do_post\n",
            "    result = await request.post(\n",
            "             ^^^^^^^^^^^^^^^^^^^\n",
            "  File \"/usr/local/lib/python3.11/dist-packages/telegram/request/_baserequest.py\", line 202, in post\n",
            "    result = await self._request_wrapper(\n",
            "             ^^^^^^^^^^^^^^^^^^^^^^^^^^^^\n",
            "  File \"/usr/local/lib/python3.11/dist-packages/telegram/request/_baserequest.py\", line 385, in _request_wrapper\n",
            "    raise Conflict(message)\n",
            "telegram.error.Conflict: Conflict: terminated by other getUpdates request; make sure that only one bot instance is running\n",
            "ERROR:telegram.ext.Application:No error handlers are registered, logging exception.\n",
            "Traceback (most recent call last):\n",
            "  File \"/usr/local/lib/python3.11/dist-packages/telegram/ext/_updater.py\", line 750, in _network_loop_retry\n",
            "    if not await do_action():\n",
            "           ^^^^^^^^^^^^^^^^^\n",
            "  File \"/usr/local/lib/python3.11/dist-packages/telegram/ext/_updater.py\", line 744, in do_action\n",
            "    return action_cb_task.result()\n",
            "           ^^^^^^^^^^^^^^^^^^^^^^^\n",
            "  File \"/usr/lib/python3.11/asyncio/futures.py\", line 203, in result\n",
            "    raise self._exception.with_traceback(self._exception_tb)\n",
            "  File \"/usr/lib/python3.11/asyncio/tasks.py\", line 277, in __step\n",
            "    result = coro.send(None)\n",
            "             ^^^^^^^^^^^^^^^\n",
            "  File \"/usr/local/lib/python3.11/dist-packages/telegram/ext/_updater.py\", line 371, in polling_action_cb\n",
            "    updates = await self.bot.get_updates(\n",
            "              ^^^^^^^^^^^^^^^^^^^^^^^^^^^\n",
            "  File \"/usr/local/lib/python3.11/dist-packages/telegram/ext/_extbot.py\", line 650, in get_updates\n",
            "    updates = await super().get_updates(\n",
            "              ^^^^^^^^^^^^^^^^^^^^^^^^^^\n",
            "  File \"/usr/local/lib/python3.11/dist-packages/telegram/_bot.py\", line 4480, in get_updates\n",
            "    await self._post(\n",
            "  File \"/usr/local/lib/python3.11/dist-packages/telegram/_bot.py\", line 619, in _post\n",
            "    return await self._do_post(\n",
            "           ^^^^^^^^^^^^^^^^^^^^\n",
            "  File \"/usr/local/lib/python3.11/dist-packages/telegram/ext/_extbot.py\", line 354, in _do_post\n",
            "    return await super()._do_post(\n",
            "           ^^^^^^^^^^^^^^^^^^^^^^^\n",
            "  File \"/usr/local/lib/python3.11/dist-packages/telegram/_bot.py\", line 648, in _do_post\n",
            "    result = await request.post(\n",
            "             ^^^^^^^^^^^^^^^^^^^\n",
            "  File \"/usr/local/lib/python3.11/dist-packages/telegram/request/_baserequest.py\", line 202, in post\n",
            "    result = await self._request_wrapper(\n",
            "             ^^^^^^^^^^^^^^^^^^^^^^^^^^^^\n",
            "  File \"/usr/local/lib/python3.11/dist-packages/telegram/request/_baserequest.py\", line 385, in _request_wrapper\n",
            "    raise Conflict(message)\n",
            "telegram.error.Conflict: Conflict: terminated by other getUpdates request; make sure that only one bot instance is running\n",
            "ERROR:telegram.ext.Application:No error handlers are registered, logging exception.\n",
            "Traceback (most recent call last):\n",
            "  File \"/usr/local/lib/python3.11/dist-packages/telegram/ext/_updater.py\", line 750, in _network_loop_retry\n",
            "    if not await do_action():\n",
            "           ^^^^^^^^^^^^^^^^^\n",
            "  File \"/usr/local/lib/python3.11/dist-packages/telegram/ext/_updater.py\", line 744, in do_action\n",
            "    return action_cb_task.result()\n",
            "           ^^^^^^^^^^^^^^^^^^^^^^^\n",
            "  File \"/usr/lib/python3.11/asyncio/futures.py\", line 203, in result\n",
            "    raise self._exception.with_traceback(self._exception_tb)\n",
            "  File \"/usr/lib/python3.11/asyncio/tasks.py\", line 277, in __step\n",
            "    result = coro.send(None)\n",
            "             ^^^^^^^^^^^^^^^\n",
            "  File \"/usr/local/lib/python3.11/dist-packages/telegram/ext/_updater.py\", line 371, in polling_action_cb\n",
            "    updates = await self.bot.get_updates(\n",
            "              ^^^^^^^^^^^^^^^^^^^^^^^^^^^\n",
            "  File \"/usr/local/lib/python3.11/dist-packages/telegram/ext/_extbot.py\", line 650, in get_updates\n",
            "    updates = await super().get_updates(\n",
            "              ^^^^^^^^^^^^^^^^^^^^^^^^^^\n",
            "  File \"/usr/local/lib/python3.11/dist-packages/telegram/_bot.py\", line 4480, in get_updates\n",
            "    await self._post(\n",
            "  File \"/usr/local/lib/python3.11/dist-packages/telegram/_bot.py\", line 619, in _post\n",
            "    return await self._do_post(\n",
            "           ^^^^^^^^^^^^^^^^^^^^\n",
            "  File \"/usr/local/lib/python3.11/dist-packages/telegram/ext/_extbot.py\", line 354, in _do_post\n",
            "    return await super()._do_post(\n",
            "           ^^^^^^^^^^^^^^^^^^^^^^^\n",
            "  File \"/usr/local/lib/python3.11/dist-packages/telegram/_bot.py\", line 648, in _do_post\n",
            "    result = await request.post(\n",
            "             ^^^^^^^^^^^^^^^^^^^\n",
            "  File \"/usr/local/lib/python3.11/dist-packages/telegram/request/_baserequest.py\", line 202, in post\n",
            "    result = await self._request_wrapper(\n",
            "             ^^^^^^^^^^^^^^^^^^^^^^^^^^^^\n",
            "  File \"/usr/local/lib/python3.11/dist-packages/telegram/request/_baserequest.py\", line 385, in _request_wrapper\n",
            "    raise Conflict(message)\n",
            "telegram.error.Conflict: Conflict: terminated by other getUpdates request; make sure that only one bot instance is running\n",
            "ERROR:telegram.ext.Application:No error handlers are registered, logging exception.\n",
            "Traceback (most recent call last):\n",
            "  File \"/usr/local/lib/python3.11/dist-packages/telegram/ext/_updater.py\", line 750, in _network_loop_retry\n",
            "    if not await do_action():\n",
            "           ^^^^^^^^^^^^^^^^^\n",
            "  File \"/usr/local/lib/python3.11/dist-packages/telegram/ext/_updater.py\", line 744, in do_action\n",
            "    return action_cb_task.result()\n",
            "           ^^^^^^^^^^^^^^^^^^^^^^^\n",
            "  File \"/usr/lib/python3.11/asyncio/futures.py\", line 203, in result\n",
            "    raise self._exception.with_traceback(self._exception_tb)\n",
            "  File \"/usr/lib/python3.11/asyncio/tasks.py\", line 277, in __step\n",
            "    result = coro.send(None)\n",
            "             ^^^^^^^^^^^^^^^\n",
            "  File \"/usr/local/lib/python3.11/dist-packages/telegram/ext/_updater.py\", line 371, in polling_action_cb\n",
            "    updates = await self.bot.get_updates(\n",
            "              ^^^^^^^^^^^^^^^^^^^^^^^^^^^\n",
            "  File \"/usr/local/lib/python3.11/dist-packages/telegram/ext/_extbot.py\", line 650, in get_updates\n",
            "    updates = await super().get_updates(\n",
            "              ^^^^^^^^^^^^^^^^^^^^^^^^^^\n",
            "  File \"/usr/local/lib/python3.11/dist-packages/telegram/_bot.py\", line 4480, in get_updates\n",
            "    await self._post(\n",
            "  File \"/usr/local/lib/python3.11/dist-packages/telegram/_bot.py\", line 619, in _post\n",
            "    return await self._do_post(\n",
            "           ^^^^^^^^^^^^^^^^^^^^\n",
            "  File \"/usr/local/lib/python3.11/dist-packages/telegram/ext/_extbot.py\", line 354, in _do_post\n",
            "    return await super()._do_post(\n",
            "           ^^^^^^^^^^^^^^^^^^^^^^^\n",
            "  File \"/usr/local/lib/python3.11/dist-packages/telegram/_bot.py\", line 648, in _do_post\n",
            "    result = await request.post(\n",
            "             ^^^^^^^^^^^^^^^^^^^\n",
            "  File \"/usr/local/lib/python3.11/dist-packages/telegram/request/_baserequest.py\", line 202, in post\n",
            "    result = await self._request_wrapper(\n",
            "             ^^^^^^^^^^^^^^^^^^^^^^^^^^^^\n",
            "  File \"/usr/local/lib/python3.11/dist-packages/telegram/request/_baserequest.py\", line 385, in _request_wrapper\n",
            "    raise Conflict(message)\n",
            "telegram.error.Conflict: Conflict: terminated by other getUpdates request; make sure that only one bot instance is running\n",
            "ERROR:telegram.ext.Application:No error handlers are registered, logging exception.\n",
            "Traceback (most recent call last):\n",
            "  File \"/usr/local/lib/python3.11/dist-packages/telegram/ext/_updater.py\", line 750, in _network_loop_retry\n",
            "    if not await do_action():\n",
            "           ^^^^^^^^^^^^^^^^^\n",
            "  File \"/usr/local/lib/python3.11/dist-packages/telegram/ext/_updater.py\", line 744, in do_action\n",
            "    return action_cb_task.result()\n",
            "           ^^^^^^^^^^^^^^^^^^^^^^^\n",
            "  File \"/usr/lib/python3.11/asyncio/futures.py\", line 203, in result\n",
            "    raise self._exception.with_traceback(self._exception_tb)\n",
            "  File \"/usr/lib/python3.11/asyncio/tasks.py\", line 277, in __step\n",
            "    result = coro.send(None)\n",
            "             ^^^^^^^^^^^^^^^\n",
            "  File \"/usr/local/lib/python3.11/dist-packages/telegram/ext/_updater.py\", line 371, in polling_action_cb\n",
            "    updates = await self.bot.get_updates(\n",
            "              ^^^^^^^^^^^^^^^^^^^^^^^^^^^\n",
            "  File \"/usr/local/lib/python3.11/dist-packages/telegram/ext/_extbot.py\", line 650, in get_updates\n",
            "    updates = await super().get_updates(\n",
            "              ^^^^^^^^^^^^^^^^^^^^^^^^^^\n",
            "  File \"/usr/local/lib/python3.11/dist-packages/telegram/_bot.py\", line 4480, in get_updates\n",
            "    await self._post(\n",
            "  File \"/usr/local/lib/python3.11/dist-packages/telegram/_bot.py\", line 619, in _post\n",
            "    return await self._do_post(\n",
            "           ^^^^^^^^^^^^^^^^^^^^\n",
            "  File \"/usr/local/lib/python3.11/dist-packages/telegram/ext/_extbot.py\", line 354, in _do_post\n",
            "    return await super()._do_post(\n",
            "           ^^^^^^^^^^^^^^^^^^^^^^^\n",
            "  File \"/usr/local/lib/python3.11/dist-packages/telegram/_bot.py\", line 648, in _do_post\n",
            "    result = await request.post(\n",
            "             ^^^^^^^^^^^^^^^^^^^\n",
            "  File \"/usr/local/lib/python3.11/dist-packages/telegram/request/_baserequest.py\", line 202, in post\n",
            "    result = await self._request_wrapper(\n",
            "             ^^^^^^^^^^^^^^^^^^^^^^^^^^^^\n",
            "  File \"/usr/local/lib/python3.11/dist-packages/telegram/request/_baserequest.py\", line 385, in _request_wrapper\n",
            "    raise Conflict(message)\n",
            "telegram.error.Conflict: Conflict: terminated by other getUpdates request; make sure that only one bot instance is running\n",
            "ERROR:telegram.ext.Application:No error handlers are registered, logging exception.\n",
            "Traceback (most recent call last):\n",
            "  File \"/usr/local/lib/python3.11/dist-packages/telegram/ext/_updater.py\", line 750, in _network_loop_retry\n",
            "    if not await do_action():\n",
            "           ^^^^^^^^^^^^^^^^^\n",
            "  File \"/usr/local/lib/python3.11/dist-packages/telegram/ext/_updater.py\", line 744, in do_action\n",
            "    return action_cb_task.result()\n",
            "           ^^^^^^^^^^^^^^^^^^^^^^^\n",
            "  File \"/usr/lib/python3.11/asyncio/futures.py\", line 203, in result\n",
            "    raise self._exception.with_traceback(self._exception_tb)\n",
            "  File \"/usr/lib/python3.11/asyncio/tasks.py\", line 277, in __step\n",
            "    result = coro.send(None)\n",
            "             ^^^^^^^^^^^^^^^\n",
            "  File \"/usr/local/lib/python3.11/dist-packages/telegram/ext/_updater.py\", line 371, in polling_action_cb\n",
            "    updates = await self.bot.get_updates(\n",
            "              ^^^^^^^^^^^^^^^^^^^^^^^^^^^\n",
            "  File \"/usr/local/lib/python3.11/dist-packages/telegram/ext/_extbot.py\", line 650, in get_updates\n",
            "    updates = await super().get_updates(\n",
            "              ^^^^^^^^^^^^^^^^^^^^^^^^^^\n",
            "  File \"/usr/local/lib/python3.11/dist-packages/telegram/_bot.py\", line 4480, in get_updates\n",
            "    await self._post(\n",
            "  File \"/usr/local/lib/python3.11/dist-packages/telegram/_bot.py\", line 619, in _post\n",
            "    return await self._do_post(\n",
            "           ^^^^^^^^^^^^^^^^^^^^\n",
            "  File \"/usr/local/lib/python3.11/dist-packages/telegram/ext/_extbot.py\", line 354, in _do_post\n",
            "    return await super()._do_post(\n",
            "           ^^^^^^^^^^^^^^^^^^^^^^^\n",
            "  File \"/usr/local/lib/python3.11/dist-packages/telegram/_bot.py\", line 648, in _do_post\n",
            "    result = await request.post(\n",
            "             ^^^^^^^^^^^^^^^^^^^\n",
            "  File \"/usr/local/lib/python3.11/dist-packages/telegram/request/_baserequest.py\", line 202, in post\n",
            "    result = await self._request_wrapper(\n",
            "             ^^^^^^^^^^^^^^^^^^^^^^^^^^^^\n",
            "  File \"/usr/local/lib/python3.11/dist-packages/telegram/request/_baserequest.py\", line 385, in _request_wrapper\n",
            "    raise Conflict(message)\n",
            "telegram.error.Conflict: Conflict: terminated by other getUpdates request; make sure that only one bot instance is running\n",
            "ERROR:telegram.ext.Application:No error handlers are registered, logging exception.\n",
            "Traceback (most recent call last):\n",
            "  File \"/usr/local/lib/python3.11/dist-packages/telegram/ext/_updater.py\", line 750, in _network_loop_retry\n",
            "    if not await do_action():\n",
            "           ^^^^^^^^^^^^^^^^^\n",
            "  File \"/usr/local/lib/python3.11/dist-packages/telegram/ext/_updater.py\", line 744, in do_action\n",
            "    return action_cb_task.result()\n",
            "           ^^^^^^^^^^^^^^^^^^^^^^^\n",
            "  File \"/usr/lib/python3.11/asyncio/futures.py\", line 203, in result\n",
            "    raise self._exception.with_traceback(self._exception_tb)\n",
            "  File \"/usr/lib/python3.11/asyncio/tasks.py\", line 277, in __step\n",
            "    result = coro.send(None)\n",
            "             ^^^^^^^^^^^^^^^\n",
            "  File \"/usr/local/lib/python3.11/dist-packages/telegram/ext/_updater.py\", line 371, in polling_action_cb\n",
            "    updates = await self.bot.get_updates(\n",
            "              ^^^^^^^^^^^^^^^^^^^^^^^^^^^\n",
            "  File \"/usr/local/lib/python3.11/dist-packages/telegram/ext/_extbot.py\", line 650, in get_updates\n",
            "    updates = await super().get_updates(\n",
            "              ^^^^^^^^^^^^^^^^^^^^^^^^^^\n",
            "  File \"/usr/local/lib/python3.11/dist-packages/telegram/_bot.py\", line 4480, in get_updates\n",
            "    await self._post(\n",
            "  File \"/usr/local/lib/python3.11/dist-packages/telegram/_bot.py\", line 619, in _post\n",
            "    return await self._do_post(\n",
            "           ^^^^^^^^^^^^^^^^^^^^\n",
            "  File \"/usr/local/lib/python3.11/dist-packages/telegram/ext/_extbot.py\", line 354, in _do_post\n",
            "    return await super()._do_post(\n",
            "           ^^^^^^^^^^^^^^^^^^^^^^^\n",
            "  File \"/usr/local/lib/python3.11/dist-packages/telegram/_bot.py\", line 648, in _do_post\n",
            "    result = await request.post(\n",
            "             ^^^^^^^^^^^^^^^^^^^\n",
            "  File \"/usr/local/lib/python3.11/dist-packages/telegram/request/_baserequest.py\", line 202, in post\n",
            "    result = await self._request_wrapper(\n",
            "             ^^^^^^^^^^^^^^^^^^^^^^^^^^^^\n",
            "  File \"/usr/local/lib/python3.11/dist-packages/telegram/request/_baserequest.py\", line 385, in _request_wrapper\n",
            "    raise Conflict(message)\n",
            "telegram.error.Conflict: Conflict: terminated by other getUpdates request; make sure that only one bot instance is running\n",
            "ERROR:telegram.ext.Application:No error handlers are registered, logging exception.\n",
            "Traceback (most recent call last):\n",
            "  File \"/usr/local/lib/python3.11/dist-packages/telegram/ext/_updater.py\", line 750, in _network_loop_retry\n",
            "    if not await do_action():\n",
            "           ^^^^^^^^^^^^^^^^^\n",
            "  File \"/usr/local/lib/python3.11/dist-packages/telegram/ext/_updater.py\", line 744, in do_action\n",
            "    return action_cb_task.result()\n",
            "           ^^^^^^^^^^^^^^^^^^^^^^^\n",
            "  File \"/usr/lib/python3.11/asyncio/futures.py\", line 203, in result\n",
            "    raise self._exception.with_traceback(self._exception_tb)\n",
            "  File \"/usr/lib/python3.11/asyncio/tasks.py\", line 277, in __step\n",
            "    result = coro.send(None)\n",
            "             ^^^^^^^^^^^^^^^\n",
            "  File \"/usr/local/lib/python3.11/dist-packages/telegram/ext/_updater.py\", line 371, in polling_action_cb\n",
            "    updates = await self.bot.get_updates(\n",
            "              ^^^^^^^^^^^^^^^^^^^^^^^^^^^\n",
            "  File \"/usr/local/lib/python3.11/dist-packages/telegram/ext/_extbot.py\", line 650, in get_updates\n",
            "    updates = await super().get_updates(\n",
            "              ^^^^^^^^^^^^^^^^^^^^^^^^^^\n",
            "  File \"/usr/local/lib/python3.11/dist-packages/telegram/_bot.py\", line 4480, in get_updates\n",
            "    await self._post(\n",
            "  File \"/usr/local/lib/python3.11/dist-packages/telegram/_bot.py\", line 619, in _post\n",
            "    return await self._do_post(\n",
            "           ^^^^^^^^^^^^^^^^^^^^\n",
            "  File \"/usr/local/lib/python3.11/dist-packages/telegram/ext/_extbot.py\", line 354, in _do_post\n",
            "    return await super()._do_post(\n",
            "           ^^^^^^^^^^^^^^^^^^^^^^^\n",
            "  File \"/usr/local/lib/python3.11/dist-packages/telegram/_bot.py\", line 648, in _do_post\n",
            "    result = await request.post(\n",
            "             ^^^^^^^^^^^^^^^^^^^\n",
            "  File \"/usr/local/lib/python3.11/dist-packages/telegram/request/_baserequest.py\", line 202, in post\n",
            "    result = await self._request_wrapper(\n",
            "             ^^^^^^^^^^^^^^^^^^^^^^^^^^^^\n",
            "  File \"/usr/local/lib/python3.11/dist-packages/telegram/request/_baserequest.py\", line 385, in _request_wrapper\n",
            "    raise Conflict(message)\n",
            "telegram.error.Conflict: Conflict: terminated by other getUpdates request; make sure that only one bot instance is running\n",
            "ERROR:telegram.ext.Application:No error handlers are registered, logging exception.\n",
            "Traceback (most recent call last):\n",
            "  File \"/usr/local/lib/python3.11/dist-packages/telegram/ext/_updater.py\", line 750, in _network_loop_retry\n",
            "    if not await do_action():\n",
            "           ^^^^^^^^^^^^^^^^^\n",
            "  File \"/usr/local/lib/python3.11/dist-packages/telegram/ext/_updater.py\", line 744, in do_action\n",
            "    return action_cb_task.result()\n",
            "           ^^^^^^^^^^^^^^^^^^^^^^^\n",
            "  File \"/usr/lib/python3.11/asyncio/futures.py\", line 203, in result\n",
            "    raise self._exception.with_traceback(self._exception_tb)\n",
            "  File \"/usr/lib/python3.11/asyncio/tasks.py\", line 277, in __step\n",
            "    result = coro.send(None)\n",
            "             ^^^^^^^^^^^^^^^\n",
            "  File \"/usr/local/lib/python3.11/dist-packages/telegram/ext/_updater.py\", line 371, in polling_action_cb\n",
            "    updates = await self.bot.get_updates(\n",
            "              ^^^^^^^^^^^^^^^^^^^^^^^^^^^\n",
            "  File \"/usr/local/lib/python3.11/dist-packages/telegram/ext/_extbot.py\", line 650, in get_updates\n",
            "    updates = await super().get_updates(\n",
            "              ^^^^^^^^^^^^^^^^^^^^^^^^^^\n",
            "  File \"/usr/local/lib/python3.11/dist-packages/telegram/_bot.py\", line 4480, in get_updates\n",
            "    await self._post(\n",
            "  File \"/usr/local/lib/python3.11/dist-packages/telegram/_bot.py\", line 619, in _post\n",
            "    return await self._do_post(\n",
            "           ^^^^^^^^^^^^^^^^^^^^\n",
            "  File \"/usr/local/lib/python3.11/dist-packages/telegram/ext/_extbot.py\", line 354, in _do_post\n",
            "    return await super()._do_post(\n",
            "           ^^^^^^^^^^^^^^^^^^^^^^^\n",
            "  File \"/usr/local/lib/python3.11/dist-packages/telegram/_bot.py\", line 648, in _do_post\n",
            "    result = await request.post(\n",
            "             ^^^^^^^^^^^^^^^^^^^\n",
            "  File \"/usr/local/lib/python3.11/dist-packages/telegram/request/_baserequest.py\", line 202, in post\n",
            "    result = await self._request_wrapper(\n",
            "             ^^^^^^^^^^^^^^^^^^^^^^^^^^^^\n",
            "  File \"/usr/local/lib/python3.11/dist-packages/telegram/request/_baserequest.py\", line 385, in _request_wrapper\n",
            "    raise Conflict(message)\n",
            "telegram.error.Conflict: Conflict: terminated by other getUpdates request; make sure that only one bot instance is running\n",
            "ERROR:telegram.ext.Application:No error handlers are registered, logging exception.\n",
            "Traceback (most recent call last):\n",
            "  File \"/usr/local/lib/python3.11/dist-packages/telegram/ext/_updater.py\", line 750, in _network_loop_retry\n",
            "    if not await do_action():\n",
            "           ^^^^^^^^^^^^^^^^^\n",
            "  File \"/usr/local/lib/python3.11/dist-packages/telegram/ext/_updater.py\", line 744, in do_action\n",
            "    return action_cb_task.result()\n",
            "           ^^^^^^^^^^^^^^^^^^^^^^^\n",
            "  File \"/usr/lib/python3.11/asyncio/futures.py\", line 203, in result\n",
            "    raise self._exception.with_traceback(self._exception_tb)\n",
            "  File \"/usr/lib/python3.11/asyncio/tasks.py\", line 277, in __step\n",
            "    result = coro.send(None)\n",
            "             ^^^^^^^^^^^^^^^\n",
            "  File \"/usr/local/lib/python3.11/dist-packages/telegram/ext/_updater.py\", line 371, in polling_action_cb\n",
            "    updates = await self.bot.get_updates(\n",
            "              ^^^^^^^^^^^^^^^^^^^^^^^^^^^\n",
            "  File \"/usr/local/lib/python3.11/dist-packages/telegram/ext/_extbot.py\", line 650, in get_updates\n",
            "    updates = await super().get_updates(\n",
            "              ^^^^^^^^^^^^^^^^^^^^^^^^^^\n",
            "  File \"/usr/local/lib/python3.11/dist-packages/telegram/_bot.py\", line 4480, in get_updates\n",
            "    await self._post(\n",
            "  File \"/usr/local/lib/python3.11/dist-packages/telegram/_bot.py\", line 619, in _post\n",
            "    return await self._do_post(\n",
            "           ^^^^^^^^^^^^^^^^^^^^\n",
            "  File \"/usr/local/lib/python3.11/dist-packages/telegram/ext/_extbot.py\", line 354, in _do_post\n",
            "    return await super()._do_post(\n",
            "           ^^^^^^^^^^^^^^^^^^^^^^^\n",
            "  File \"/usr/local/lib/python3.11/dist-packages/telegram/_bot.py\", line 648, in _do_post\n",
            "    result = await request.post(\n",
            "             ^^^^^^^^^^^^^^^^^^^\n",
            "  File \"/usr/local/lib/python3.11/dist-packages/telegram/request/_baserequest.py\", line 202, in post\n",
            "    result = await self._request_wrapper(\n",
            "             ^^^^^^^^^^^^^^^^^^^^^^^^^^^^\n",
            "  File \"/usr/local/lib/python3.11/dist-packages/telegram/request/_baserequest.py\", line 385, in _request_wrapper\n",
            "    raise Conflict(message)\n",
            "telegram.error.Conflict: Conflict: terminated by other getUpdates request; make sure that only one bot instance is running\n",
            "ERROR:telegram.ext.Application:No error handlers are registered, logging exception.\n",
            "Traceback (most recent call last):\n",
            "  File \"/usr/local/lib/python3.11/dist-packages/telegram/ext/_updater.py\", line 750, in _network_loop_retry\n",
            "    if not await do_action():\n",
            "           ^^^^^^^^^^^^^^^^^\n",
            "  File \"/usr/local/lib/python3.11/dist-packages/telegram/ext/_updater.py\", line 744, in do_action\n",
            "    return action_cb_task.result()\n",
            "           ^^^^^^^^^^^^^^^^^^^^^^^\n",
            "  File \"/usr/lib/python3.11/asyncio/futures.py\", line 203, in result\n",
            "    raise self._exception.with_traceback(self._exception_tb)\n",
            "  File \"/usr/lib/python3.11/asyncio/tasks.py\", line 277, in __step\n",
            "    result = coro.send(None)\n",
            "             ^^^^^^^^^^^^^^^\n",
            "  File \"/usr/local/lib/python3.11/dist-packages/telegram/ext/_updater.py\", line 371, in polling_action_cb\n",
            "    updates = await self.bot.get_updates(\n",
            "              ^^^^^^^^^^^^^^^^^^^^^^^^^^^\n",
            "  File \"/usr/local/lib/python3.11/dist-packages/telegram/ext/_extbot.py\", line 650, in get_updates\n",
            "    updates = await super().get_updates(\n",
            "              ^^^^^^^^^^^^^^^^^^^^^^^^^^\n",
            "  File \"/usr/local/lib/python3.11/dist-packages/telegram/_bot.py\", line 4480, in get_updates\n",
            "    await self._post(\n",
            "  File \"/usr/local/lib/python3.11/dist-packages/telegram/_bot.py\", line 619, in _post\n",
            "    return await self._do_post(\n",
            "           ^^^^^^^^^^^^^^^^^^^^\n",
            "  File \"/usr/local/lib/python3.11/dist-packages/telegram/ext/_extbot.py\", line 354, in _do_post\n",
            "    return await super()._do_post(\n",
            "           ^^^^^^^^^^^^^^^^^^^^^^^\n",
            "  File \"/usr/local/lib/python3.11/dist-packages/telegram/_bot.py\", line 648, in _do_post\n",
            "    result = await request.post(\n",
            "             ^^^^^^^^^^^^^^^^^^^\n",
            "  File \"/usr/local/lib/python3.11/dist-packages/telegram/request/_baserequest.py\", line 202, in post\n",
            "    result = await self._request_wrapper(\n",
            "             ^^^^^^^^^^^^^^^^^^^^^^^^^^^^\n",
            "  File \"/usr/local/lib/python3.11/dist-packages/telegram/request/_baserequest.py\", line 385, in _request_wrapper\n",
            "    raise Conflict(message)\n",
            "telegram.error.Conflict: Conflict: terminated by other getUpdates request; make sure that only one bot instance is running\n",
            "ERROR:telegram.ext.Application:No error handlers are registered, logging exception.\n",
            "Traceback (most recent call last):\n",
            "  File \"/usr/local/lib/python3.11/dist-packages/telegram/ext/_updater.py\", line 750, in _network_loop_retry\n",
            "    if not await do_action():\n",
            "           ^^^^^^^^^^^^^^^^^\n",
            "  File \"/usr/local/lib/python3.11/dist-packages/telegram/ext/_updater.py\", line 744, in do_action\n",
            "    return action_cb_task.result()\n",
            "           ^^^^^^^^^^^^^^^^^^^^^^^\n",
            "  File \"/usr/lib/python3.11/asyncio/futures.py\", line 203, in result\n",
            "    raise self._exception.with_traceback(self._exception_tb)\n",
            "  File \"/usr/lib/python3.11/asyncio/tasks.py\", line 277, in __step\n",
            "    result = coro.send(None)\n",
            "             ^^^^^^^^^^^^^^^\n",
            "  File \"/usr/local/lib/python3.11/dist-packages/telegram/ext/_updater.py\", line 371, in polling_action_cb\n",
            "    updates = await self.bot.get_updates(\n",
            "              ^^^^^^^^^^^^^^^^^^^^^^^^^^^\n",
            "  File \"/usr/local/lib/python3.11/dist-packages/telegram/ext/_extbot.py\", line 650, in get_updates\n",
            "    updates = await super().get_updates(\n",
            "              ^^^^^^^^^^^^^^^^^^^^^^^^^^\n",
            "  File \"/usr/local/lib/python3.11/dist-packages/telegram/_bot.py\", line 4480, in get_updates\n",
            "    await self._post(\n",
            "  File \"/usr/local/lib/python3.11/dist-packages/telegram/_bot.py\", line 619, in _post\n",
            "    return await self._do_post(\n",
            "           ^^^^^^^^^^^^^^^^^^^^\n",
            "  File \"/usr/local/lib/python3.11/dist-packages/telegram/ext/_extbot.py\", line 354, in _do_post\n",
            "    return await super()._do_post(\n",
            "           ^^^^^^^^^^^^^^^^^^^^^^^\n",
            "  File \"/usr/local/lib/python3.11/dist-packages/telegram/_bot.py\", line 648, in _do_post\n",
            "    result = await request.post(\n",
            "             ^^^^^^^^^^^^^^^^^^^\n",
            "  File \"/usr/local/lib/python3.11/dist-packages/telegram/request/_baserequest.py\", line 202, in post\n",
            "    result = await self._request_wrapper(\n",
            "             ^^^^^^^^^^^^^^^^^^^^^^^^^^^^\n",
            "  File \"/usr/local/lib/python3.11/dist-packages/telegram/request/_baserequest.py\", line 385, in _request_wrapper\n",
            "    raise Conflict(message)\n",
            "telegram.error.Conflict: Conflict: terminated by other getUpdates request; make sure that only one bot instance is running\n",
            "ERROR:telegram.ext.Application:No error handlers are registered, logging exception.\n",
            "Traceback (most recent call last):\n",
            "  File \"/usr/local/lib/python3.11/dist-packages/telegram/ext/_updater.py\", line 750, in _network_loop_retry\n",
            "    if not await do_action():\n",
            "           ^^^^^^^^^^^^^^^^^\n",
            "  File \"/usr/local/lib/python3.11/dist-packages/telegram/ext/_updater.py\", line 744, in do_action\n",
            "    return action_cb_task.result()\n",
            "           ^^^^^^^^^^^^^^^^^^^^^^^\n",
            "  File \"/usr/lib/python3.11/asyncio/futures.py\", line 203, in result\n",
            "    raise self._exception.with_traceback(self._exception_tb)\n",
            "  File \"/usr/lib/python3.11/asyncio/tasks.py\", line 277, in __step\n",
            "    result = coro.send(None)\n",
            "             ^^^^^^^^^^^^^^^\n",
            "  File \"/usr/local/lib/python3.11/dist-packages/telegram/ext/_updater.py\", line 371, in polling_action_cb\n",
            "    updates = await self.bot.get_updates(\n",
            "              ^^^^^^^^^^^^^^^^^^^^^^^^^^^\n",
            "  File \"/usr/local/lib/python3.11/dist-packages/telegram/ext/_extbot.py\", line 650, in get_updates\n",
            "    updates = await super().get_updates(\n",
            "              ^^^^^^^^^^^^^^^^^^^^^^^^^^\n",
            "  File \"/usr/local/lib/python3.11/dist-packages/telegram/_bot.py\", line 4480, in get_updates\n",
            "    await self._post(\n",
            "  File \"/usr/local/lib/python3.11/dist-packages/telegram/_bot.py\", line 619, in _post\n",
            "    return await self._do_post(\n",
            "           ^^^^^^^^^^^^^^^^^^^^\n",
            "  File \"/usr/local/lib/python3.11/dist-packages/telegram/ext/_extbot.py\", line 354, in _do_post\n",
            "    return await super()._do_post(\n",
            "           ^^^^^^^^^^^^^^^^^^^^^^^\n",
            "  File \"/usr/local/lib/python3.11/dist-packages/telegram/_bot.py\", line 648, in _do_post\n",
            "    result = await request.post(\n",
            "             ^^^^^^^^^^^^^^^^^^^\n",
            "  File \"/usr/local/lib/python3.11/dist-packages/telegram/request/_baserequest.py\", line 202, in post\n",
            "    result = await self._request_wrapper(\n",
            "             ^^^^^^^^^^^^^^^^^^^^^^^^^^^^\n",
            "  File \"/usr/local/lib/python3.11/dist-packages/telegram/request/_baserequest.py\", line 385, in _request_wrapper\n",
            "    raise Conflict(message)\n",
            "telegram.error.Conflict: Conflict: terminated by other getUpdates request; make sure that only one bot instance is running\n"
          ]
        },
        {
          "output_type": "stream",
          "name": "stdout",
          "text": [
            "Bot is running... Press Ctrl+C to stop.\n"
          ]
        }
      ]
    },
    {
      "cell_type": "code",
      "source": [],
      "metadata": {
        "id": "TjcJrZjx895Q"
      },
      "execution_count": 7,
      "outputs": []
    }
  ]
}